Workbook

Sheet Review Summary
A1: Journal Entry Review
A3: Source file | B3: sample_je_errors.csv
A4: Run timestamp | B4: 2026-05-30 21:52
A5: Period(s) | B5: 2024-11, 2027-03
A6: Total entries | B6: 12
A7: Total lines | B7: 25
A8: Surfaced for review | B8: 10
A9: Share surfaced | B9: 83.3%
A10: Likely recording errors | B10: 10
A11: Anomalies to confirm | B11: 2
A13: Review status
A14: Entries with a disposition | B14: 0 of 10
A15: Support reviewed / not required | B15: 0 of 10
A17: Population shape
A18: Unique preparers (surfaced) | B18: 2
A19: Unique approvers (surfaced) | B19: 1
A20: Earliest surfaced date | B20: 2024-11-04
A21: Latest surfaced date | B21: 2027-03-01
A22: Total surfaced $ (debits) | B22: 7350.12
A24: First-pass checks (triage)
A25: Check | B25: Weight | C25: Ran? | D25: Entries surfaced | E25: % of surfaced | F25: What it needs
A26: Posted on a weekend | B26: 2 | C26: Yes | D26: =COUNTIF('Review Queue'!F:F,"*"&"WEEKEND_POSTING"&"*") | E26: =IFERROR(D26/10,0) | F26: entry_date
A27: Posted after the period it affects | B27: 3 | C27: Yes | D27: =COUNTIF('Review Queue'!F:F,"*"&"AFTER_PERIOD_END"&"*") | E27: =IFERROR(D27/10,0) | F27: entry_date,period
A28: Posted in the last days of the period | B28: 1 | C28: Yes | D28: =COUNTIF('Review Queue'!F:F,"*"&"PERIOD_END_CONCENTRATION"&"*") | E28: =IFERROR(D28/10,0) | F28: entry_date
A29: Posted outside business hours | B29: 1 | C29: No — field missing | D29: =COUNTIF('Review Queue'!F:F,"*"&"OFFHOURS_POSTING"&"*") | E29: =IFERROR(D29/10,0) | F29: posted_at
A30: Round-dollar amount | B30: 1 | C30: Yes | D30: =COUNTIF('Review Queue'!F:F,"*"&"ROUND_AMOUNT"&"*") | E30: =IFERROR(D30/10,0) | F30: amount
A31: Just below an approval threshold | B31: 2 | C31: Yes | D31: =COUNTIF('Review Queue'!F:F,"*"&"BELOW_THRESHOLD"&"*") | E31: =IFERROR(D31/10,0) | F31: amount
A32: Unusually large amount | B32: 1 | C32: Yes | D32: =COUNTIF('Review Queue'!F:F,"*"&"LARGE_OUTLIER"&"*") | E32: =IFERROR(D32/10,0) | F32: amount
A33: Seldom-used account | B33: 2 | C33: Yes | D33: =COUNTIF('Review Queue'!F:F,"*"&"SELDOM_ACCOUNT"&"*") | E33: =IFERROR(D33/10,0) | F33: account
A34: Sensitive account | B34: 1 | C34: Yes | D34: =COUNTIF('Review Queue'!F:F,"*"&"SENSITIVE_ACCOUNT"&"*") | E34: =IFERROR(D34/10,0) | F34: account_name
A35: Manual entry | B35: 1 | C35: Yes | D35: =COUNTIF('Review Queue'!F:F,"*"&"MANUAL_SOURCE"&"*") | E35: =IFERROR(D35/10,0) | F35: source
A36: Preparer is also approver | B36: 3 | C36: Yes | D36: =COUNTIF('Review Queue'!F:F,"*"&"SOD_CONFLICT"&"*") | E36: =IFERROR(D36/10,0) | F36: entered_by,approved_by
A37: Missing description | B37: 2 | C37: Yes | D37: =COUNTIF('Review Queue'!F:F,"*"&"BLANK_DESCRIPTION"&"*") | E37: =IFERROR(D37/10,0) | F37: description
A38: Suspicious description keyword | B38: 2 | C38: Yes | D38: =COUNTIF('Review Queue'!F:F,"*"&"SUSPICIOUS_KEYWORD"&"*") | E38: =IFERROR(D38/10,0) | F38: description
A39: Entry does not balance | B39: 3 | C39: Yes | D39: =COUNTIF('Review Queue'!F:F,"*"&"UNBALANCED_ENTRY"&"*") | E39: =IFERROR(D39/10,0) | F39: amount
A40: Possible duplicate entry | B40: 3 | C40: Yes | D40: =COUNTIF('Review Queue'!F:F,"*"&"DUPLICATE_ENTRY"&"*") | E40: =IFERROR(D40/10,0) | F40: account,amount
A41: Reversed shortly after posting | B41: 2 | C41: Yes | D41: =COUNTIF('Review Queue'!F:F,"*"&"QUICK_REVERSAL"&"*") | E41: =IFERROR(D41/10,0) | F41: entry_date,account,amount
A42: Gap in entry numbering | B42: 1 | C42: Yes | D42: =COUNTIF('Review Queue'!F:F,"*"&"NUMBERING_GAP"&"*") | E42: =IFERROR(D42/10,0) | F42: je_id
A43: Posted by an infrequent user | B43: 2 | C43: Yes | D43: =COUNTIF('Review Queue'!F:F,"*"&"RARE_USER"&"*") | E43: =IFERROR(D43/10,0) | F43: entered_by
A44: All lines on one side | B44: 3 | C44: Yes | D44: =COUNTIF('Review Queue'!F:F,"*"&"SINGLE_SIDED_ENTRY"&"*") | E44: =IFERROR(D44/10,0) | F44: debit,credit
...

Sheet Review Queue
A1: JE ID | B1: Review priority | C1: Priority | D1: # Checks | E1: Why surfaced | F1: Check IDs | G1: Entry Date | H1: Period | I1: Lines | J1: Total Debit | K1: Total Credit | L1: Net | M1: Preparer | N1: Approver | O1: Source | P1: Description | Q1: Flag Type | R1: Disposition | S1: Support Status | T1: Amount? | U1: Date? | V1: Account? | W1: Description? | X1: Support | Y1: Correction | Z1: Reviewer | AA1: Review Date | AB1: Conclusion
A2: ERR-0001 | B2: 7 | C2: High | D2: 3 | E2: [ROUND_AMOUNT] Round amount $1,000 ; [UNBALANCED_ENTRY] Out of balance by $1,500.00 ; [SINGLE_SIDED_ENTRY] All lines are debits; no offsetting side | F2: ROUND_AMOUNT, UNBALANCED_ENTRY, SINGLE_SIDED_ENTRY | G2: 2024-11-04 | H2: 2024-11 | I2: 2 | J2: 1500 | K2: 0 | L2: 1500 | M2: ksmith | N2: mgr_ortiz | O2: System | P2: Two debits no credit | Q2: Both | R2: Open
A3: ERR-0002 | B3: 6 | C3: High | D3: 2 | E3: [UNBALANCED_ENTRY] Out of balance by $-800.00 ; [DEBIT_AND_CREDIT_SAME_LINE] A line has both a debit and a credit amount | F3: UNBALANCED_ENTRY, DEBIT_AND_CREDIT_SAME_LINE | G3: 2024-11-05 | H3: 2024-11 | I3: 2 | J3: 800 | K3: 1600 | L3: -800 | M3: rlee | N3: mgr_ortiz | O3: System | P3: Both DR and CR on a line | Q3: Accuracy | R3: Open
A4: ERR-0003 | B4: 3 | C4: Medium | D4: 2 | E4: [LARGE_OUTLIER] Large amount $1,200 (top 1%) ; [BLANK_LINE_AMOUNT] 1 line(s) with no debit or credit amount | F4: LARGE_OUTLIER, BLANK_LINE_AMOUNT | G4: 2024-11-06 | H4: 2024-11 | I4: 3 | J4: 1200 | K4: 1200 | L4: 0 | M4: ksmith | N4: mgr_ortiz | O4: System | P4: Has a blank line | Q4: Both | R4: Open
A5: ERR-0005 | B5: 3 | C5: Medium | D5: 1 | E5: [MISSING_ACCOUNT] 1 line(s) with no account number | F5: MISSING_ACCOUNT | G5: 2024-11-08 | H5: 2024-11 | I5: 2 | J5: 700 | K5: 700 | L5: 0 | M5: ksmith | N5: mgr_ortiz | O5: System | P5: Missing account number | Q5: Accuracy | R5: Open
A6: ERR-0004 | B6: 2 | C6: Low | D6: 1 | E6: [NEGATIVE_DR_CR] Negative value in a debit/credit column | F6: NEGATIVE_DR_CR | G6: 2024-11-07 | H6: 2024-11 | I6: 2 | J6: -500 | K6: -500 | L6: 0 | M6: rlee | N6: mgr_ortiz | O6: System | P6: Negative posted | Q6: Accuracy | R6: Open
A7: ERR-0008 | B7: 2 | C7: Low | D7: 1 | E7: [PERIOD_DATE_MISMATCH] Dated 2024-10-15 but labelled period 2024-11 | F7: PERIOD_DATE_MISMATCH | G7: 2024-11-13 | H7: 2024-11 | I7: 2 | J7: 300 | K7: 300 | L7: 0 | M7: rlee | N7: mgr_ortiz | O7: System | P7: Wrong period | Q7: Accuracy | R7: Open
A8: ERR-0010 | B8: 2 | C8: Low | D8: 1 | E8: [FUTURE_DATE] Dated in the future (2027-03-01) | F8: FUTURE_DATE | G8: 2027-03-01 | H8: 2027-03 | I8: 2 | J8: 400 | K8: 400 | L8: 0 | M8: rlee | N8: mgr_ortiz | O8: System | P8: Future dated | Q8: Accuracy | R8: Open
A9: ERR-0006 | B9: 1 | C9: Low | D9: 1 | E9: [ACCOUNT_NAME_INCONSISTENT] Account 7000 recorded under multiple names: Bank, Cash | F9: ACCOUNT_NAME_INCONSISTENT | G9: 2024-11-11 | H9: 2024-11 | I9: 2 | J9: 900 | K9: 900 | L9: 0 | M9: rlee | N9: mgr_ortiz | O9: System | P9: Account named Bank | Q9: Accuracy | R9: Open
A10: ERR-0007 | B10: 1 | C10: Low | D10: 1 | E10: [ACCOUNT_NAME_INCONSISTENT] Account 7000 recorded under multiple names: Bank, Cash | F10: ACCOUNT_NAME_INCONSISTENT | G10: 2024-11-12 | H10: 2024-11 | I10: 2 | J10: 950 | K10: 950 | L10: 0 | M10: ksmith | N10: mgr_ortiz | O10: System | P10: Same account named Cash | Q10: Accuracy | R10: Open
A11: ERR-0009 | B11: 1 | C11: Low | D11: 1 | E11: [EXCESS_PRECISION] Amount with sub-cent precision (e.g. 100.12345) | F11: EXCESS_PRECISION | G11: 2024-11-14 | H11: 2024-11 | I11: 2 | J11: 100.12 | K11: 100.12 | L11: 0 | M11: ksmith | N11: mgr_ortiz | O11: System | P11: Sub-cent amount | Q11: Accuracy | R11: Open

Sheet Support Log
A1: JE ID | B1: Support | C1: Type | D1: Covers | E1: Agrees? | F1: Note
A2: — | B2: No support items recorded yet.

Sheet Triage checks
A1: Check ID | B1: Check | C1: Category | D1: Weight | E1: Fields needed | F1: Ran? | G1: Description
A2: WEEKEND_POSTING | B2: Posted on a weekend | C2: Risk | D2: 2 | E2: entry_date | F2: Yes | G2: Entry recorded on a Saturday or Sunday — outside normal close cadence.
A3: AFTER_PERIOD_END | B3: Posted after the period it affects | C3: Risk | D3: 3 | E3: entry_date,period | F3: Yes | G3: Entry recorded after the close of the accounting period (possible back-dating).
A4: PERIOD_END_CONCENTRATION | B4: Posted in the last days of the period | C4: Risk | D4: 1 | E4: entry_date | F4: Yes | G4: Entry recorded in the final days of the month — period-end pressure window.
A5: OFFHOURS_POSTING | B5: Posted outside business hours | C5: Risk | D5: 1 | E5: posted_at | F5: No | G5: Entry timestamp is late night/early morning — unusual posting time.
A6: ROUND_AMOUNT | B6: Round-dollar amount | C6: Risk | D6: 1 | E6: amount | F6: Yes | G6: A line amount is an exact multiple of 1,000 — often estimates or plugs.
A7: BELOW_THRESHOLD | B7: Just below an approval threshold | C7: Risk | D7: 2 | E7: amount | F7: Yes | G7: A line amount sits just under a known approval limit — possible threshold gaming.
A8: LARGE_OUTLIER | B8: Unusually large amount | C8: Risk | D8: 1 | E8: amount | F8: Yes | G8: A line amount is in the top percentile of the population.
A9: SELDOM_ACCOUNT | B9: Seldom-used account | C9: Risk | D9: 2 | E9: account | F9: Yes | G9: An account touched by only one entry in the period — rarely-used accounts carry higher risk.
A10: SENSITIVE_ACCOUNT | B10: Sensitive account | C10: Risk | D10: 1 | E10: account_name | F10: Yes | G10: A line hits a higher-risk account class (suspense, reserve, equity, revenue, IC, etc.).
A11: MANUAL_SOURCE | B11: Manual entry | C11: Risk | D11: 1 | E11: source | F11: Yes | G11: Entry was posted manually rather than system-generated.
A12: SOD_CONFLICT | B12: Preparer is also approver | C12: Risk | D12: 3 | E12: entered_by,approved_by | F12: Yes | G12: Same user prepared and approved the entry — segregation-of-duties conflict.
A13: BLANK_DESCRIPTION | B13: Missing description | C13: Risk | D13: 2 | E13: description | F13: Yes | G13: Entry has no narrative — undocumented entries are harder to substantiate.
... A29: UNKNOWN_ACCOUNT | B29: Account not in chart of accounts | C29: Accuracy | D29: 2 | E29: account | F29: Yes | G29: A line posts to an account not present in the uploaded chart of accounts. Runs only when a chart of accounts is provided.

Sheet Triage
A1: Triage Notes
A3: Triage notes — top 10 exception(s)
A5: _Investigative leads for auditor judgement, not conclusions. Generated locally; no data left this machine._
A7: ERR-0001 · risk 7 · 3 test(s)
A8: Entry date 2024-11-04, period 2024-11, net $1,500.00, preparer ksmith, approver mgr_ortiz, source System.
A9: **Why flagged:** [ROUND_AMOUNT] Round amount $1,000 ; [UNBALANCED_ENTRY] Out of balance by $1,500.00 ; [SINGLE_SIDED_ENTRY] All lines are debits; no offsetting side
A10: **Suggested procedures:**
A11: - Round amounts often signal estimates or plugs — trace to primary documentation, not a calculation.
A12: - An out-of-balance entry indicates a posting/data error or partial entry — reconcile both sides before relying on it.
A14: ERR-0002 · risk 6 · 2 test(s)
A15: Entry date 2024-11-05, period 2024-11, net $-800.00, preparer rlee, approver mgr_ortiz, source System.
A16: **Why flagged:** [UNBALANCED_ENTRY] Out of balance by $-800.00 ; [DEBIT_AND_CREDIT_SAME_LINE] A line has both a debit and a credit amount
... A59: **Suggested procedures:**
